Workbook

Sheet LENIN
B1: REPORTE DE ASISTENCIA
B2: FECHA | C2: CLIMA | D2: PREDICADOR | E2: TEMA
H3: DATOS REDES SOCIALES
B4: SERVICIO | D4: 1.4166667 | E4: 1.5 | F4: 6:00 p.m. | H4: SERVICIO | J4: 1.4166667
B5: ASISTENTES AL SERVICIO | D5: =D11-D12-D13-D14+D15+D19+D23+D24+D9 -> 0 | E5: =E11-E12-E13-E14+E15+E19+E23+E24+E9 -> 0 | F5: =F11-F12-F13-F14+F15+F19+F23+F24+F9 -> 0 | H5: FACEBOOK | I5: Rep. 15 seg. con sonido (ROCK)
B6: ASISTENCIA NIÑOS/NEON | D6: =D43+D45 -> 0 | E6: =E43+E45 -> 0 | F6: =F43+F45 -> 0 | I6: Rep. al menos 1 minuto
B7: ASISTENCIA PRESENCIAL TOTAL | D7: =D5+E5+D6+E6+F5+F6 -> 0 | H7: YOUTUBE | I7: Views al terminar el servicio (ROCK)
B8: DESCRIPCION | H8: ASISTENCIA EN LÍNEA | J8: =SUM(J5+J7) -> 0
B9: AUDITORIO
B10: VOLUNTARIOS
B11: PRIMERAS IMPRESIONES
B12: ANFITRIONES
B13: ESTACIONAMIENTO
B14: JARDIN
B15: CRECE
B16: EVENTOS
B17: ALABANZA
B18: PRODUCCIÓN
B19: KIDS
B20: TRANSPORTE
... B24: JÓVENES
B25: TOTAL DE VOLUNTARIOS | D25: =D11+D15+D16+D17+D18+D19+D20+D21+D22+D23+D24 -> 0 | E25: =E11+E15+E16+E17+E18+E19+E20+E21+E22+E23+E24 -> 0 | F25: =F11+F15+F16+F17+F18+F19+F20+F21+F22+F23+F24 -> 0
B26: DATOS DE CONEXIÓN
B27: TOTAL DE INV. ESP. (PRIMERA VEZ)
B28: TOTAL PERSONAS QUE ACEPTARON A CRISTO
B29: BAUTIZOS
B30: RECEPCIÓN INVITADOS (MENSUAL)
B31: RUTAS CAMIONES
B32: REGISTRO CRECE MODULO 1
B33: REGISTRO CRECE MODULO 2
B34: KIDS
B35: 0 A 1.5 AÑOS / MATERNAL 1
B36: 1.5 A 2 AÑOS / MATERNAL 2
B37: 3 AÑOS / KINDER 1
... B42: 9 AÑOS / 4° GRADO
B43: TOTAL DE NIÑOS | D43: {=SUM(D35:D42)} -> 0 | E43: {=SUM(E35:E42)} -> 0 | F43: =SUM(F35:F42) -> 0
B44: JÓVENES
B45: NEON (5° Y 6° PRIMARIA)
B46: SABADO | D46: 1.7083333
B47: GRUPOS SECUNDARIAS ( 1 A 3 GRADO )
...

Sheet PASTORES
C1: REPORTE DE ASISTENCIA
C2: FECHA | D2: CLIMA | E2: PREDICADOR | F2: TEMA
C3: {=LENIN!B3} | D3: {=LENIN!C3} | E3: {=LENIN!D3} | F3: =LENIN!E3 | I3: DATOS REDES SOCIALES
C4: SERVICIO | E4: 1.4166667 | F4: 1.5 | G4: 06:00 p.m. | I4: SERVICIO | K4: 1.4166667
C5: ASISTENTES AL SERVICIO | E5: =LENIN!D5 -> 0 | F5: {=LENIN!E5} -> 0 | G5: {=LENIN!F5} -> 0 | I5: FACEBOOK | J5: Rep. 15 seg. con sonido (ROCK) | K5: =LENIN!J5
C6: ASISTENCIA NIÑOS/NEON | E6: {=LENIN!D6} -> 0 | F6: {=LENIN!E6} -> 0 | G6: {=LENIN!F6} -> 0 | J6: Rep. al menos 1 minuto | K6: =LENIN!J6
C7: ASISTENCIA PRESENCIAL TOTAL | E7: =LENIN!D7 -> 0 | I7: YOUTUBE | J7: Views al terminar el servicio (ROCK) | K7: =LENIN!J7
C8: VOLUNTARIOS DE DOMINGO | I8: ASISTENCIA EN LÍNEA | K8: {=LENIN!J8} -> 0
C9: PRIMERAS IMPRESIONES | E9: {=LENIN!D11} | F9: {=LENIN!E11} | G9: {=LENIN!F11}
C10: CRECE | E10: =LENIN!D15 | F10: =LENIN!E15 | G10: =LENIN!F15
C11: EVENTOS | E11: =LENIN!D16 | F11: =LENIN!E16 | G11: =LENIN!F16
C12: ALABANZA | E12: =LENIN!D17 | F12: =LENIN!E17 | G12: =LENIN!F17
C13: PRODUCCIÓN | E13: =LENIN!D18 | F13: =LENIN!E18 | G13: =LENIN!F18
C14: KIDS | E14: =LENIN!D19 | F14: =LENIN!E19 | G14: =LENIN!F19
C15: TRANSPORTE | E15: =LENIN!D20 | F15: =LENIN!E20 | G15: =LENIN!F20
C16: CONTADORES | E16: =LENIN!D21 | F16: =LENIN!E21 | G16: =LENIN!F21
C17: SIRVIENDO EN AMOR | E17: =LENIN!D22 | F17: =LENIN!E22 | G17: =LENIN!F22
C18: NEON (5° Y 6° PRIMARIA) | E18: =LENIN!D23 | F18: =LENIN!E23 | G18: =LENIN!F23
C19: JÓVENES (SABADO Y DOMINGO) | E19: =LENIN!D24 | F19: =LENIN!E24 | G19: =LENIN!F24
C20: TOTAL DE VOLUNTARIOS | E20: =SUM(E9:E19) -> 0 | F20: =SUM(F9:F19) -> 0 | G20: =SUM(G9:G19) -> 0
C21: DATOS DE CONEXIÓN
C22: TOTAL DE INV. ESP. (PRIMERA VEZ) | E22: {=LENIN!D27} | F22: {=LENIN!E27} | G22: {=LENIN!F27}
C23: TOTAL PERSONAS QUE ACEPTARON A CRISTO | E23: {=LENIN!D28} | F23: {=LENIN!E28} | G23: =LENIN!F28
C24: BAUTIZOS | E24: {=LENIN!D29} | F24: {=LENIN!E29} | G24: =LENIN!F29
C25: RECEPCIÓN INVITADOS (MENSUAL) | E25: {=LENIN!D30} | F25: {=LENIN!E30} | G25: =LENIN!F30
C26: RUTAS CAMIONES | E26: {=LENIN!D31} | F26: {=LENIN!E31} | G26: =LENIN!F31
C27: REGISTRO CRECE MODULO 1 | E27: {=LENIN!D32} | F27: {=LENIN!E32} | G27: =LENIN!F32
C28: REGISTRO CRECE MODULO 2 | E28: {=LENIN!D33} | F28: {=LENIN!E33} | G28: =LENIN!F33
C29: MINUTA DE REUNIÓN
C30: HORA DE INICIO | E30: 1.4166667 | F30: 1.5 | G30: 06:00 p.m.
C31: ALABANZA
C32: ORACION POR MEXICO
C33: BIENVENIDA
C34: OFRENDAS Y SALIDA DE NEON
C35: NOTICIAS
C36: MENSAJE
C37: MINISTRACIÓN
C38: CIERRE
C39: HORA DE SALIDA
C40: TIEMPO TOTAL DE REUNIÓN
...
